Workbook

Sheet Instrucciones
A1: AMBERES INTELLIGENCE – MODELO CONSOLIDADO
A3: QUÉ ES ESTE ARCHIVO
A4: Un solo archivo con todas las pestañas que el software reconoce por su nombre y contenido: P&L (6 hojas), Evaluación de proyectos (Panel, Supuestos, Ingresos, Costos, Estado de Resultados, Financiamiento, Flujo de Caja, Resumen, Escenarios, Valoración, Ratios), Balance y M&A.
A6: CÓMO USARLO
A7: 1. Pegue sus datos en las hojas de P&L (una hoja por empresa y escenario: Real, Budget, Forecast) y/o en Supuestos (celdas amarillas).
A8: 2. Suba el archivo a Amberes Intelligence. Cada pestaña se identifica sola; las vacías se marcan como opcionales.
A9: 3. Si solo sube un P&L, el software construye por sí mismo el flujo de caja operacional y financiero, el balance (que cuadra) y la valoración M&A, rotulando como "estimado" todo lo que no estaba cargado.
A10: 4. Balance, Estado de Flujo de Caja y M&A son opcionales: complételos solo si desea reemplazar las estimaciones. Si sube solo un Balance o solo un Flujo de Caja, el software completa los otros informes de forma aproximada (no todas las cuentas se pueden traspasar de un informe a otro; lo estimado se rotula).
A12: CÓDIGO DE COLORES
A13: Celdas amarillas con texto azul = datos que usted ingresa. Fondo blanco = fórmulas, no editar.
A15: IMPORTANTE
A16: Las hojas de ejemplo incluidas son datos ilustrativos y no están relacionadas entre sí (el P&L es de una empresa de servicios; la evaluación es un proyecto distinto). Reemplácelos con sus cifras.
... A18: Los resultados son referenciales y deben ser validados por un profesional antes de decisiones de inversión, financiamiento o transacciones.

Sheet Panel de Control
A1: MODELO DE EVALUACIÓN DE PROYECTOS
V2: Inversión | W2: USD
A3: INFORMACIÓN DEL PROYECTO | V3: Desinversión | W3: CLP
V4: Fusión | W4: EUR
A5: Nombre del Proyecto: | B5: Proyecto Ejemplo | V5: Adquisición | W5: ARS | X5: Peso Argentino
A6: Tipo de Operación: | B6: Inversión | W6: MXN | X6: Peso Mexicano
A7: Fecha de Evaluación: | B7: 46023 | W7: COP | X7: Peso Colombiano
A8: Moneda: | B8: CLP | W8: PEN | X8: Sol Peruano
A9: Unidad (miles/millones): | B9: miles | W9: UYU | X9: Peso Uruguayo
W10: CRC | X10: Colón Costarricense
A11: PARÁMETROS DE ANÁLISIS
A13: Horizonte de Evaluación (meses): | B13: 60
A14: Tasa de Descuento (WACC): | B14: 0.12
A15: Tasa Impositiva: | B15: 0.27
A17: INDICADORES PRINCIPALES
A19: VAN (Valor Actual Neto): | B19: =Resumen!B5 -> -24259406
A20: TIR (Tasa Interna de Retorno): | B20: =Resumen!B7 -> -0.025297748
A21: Período de Recuperación (meses): | B21: =Resumen!B8 -> -
A22: ROI (Return on Investment): | B22: =Resumen!B9 -> -0.097106988

Sheet Supuestos
A1: SUPUESTOS PRINCIPALES
A3: INVERSIÓN INICIAL
A4: Inversión en Activos Fijos: | B4: 50000000
A5: Capital de Trabajo Inicial: | B5: 7000000
A6: Gastos Pre-operativos: | B6: 500000
A8: INGRESOS
A9: Ingresos Mensuales Año 1: | B9: 10700000
A10: Crecimiento Anual Ingresos: | B10: 0.07
A12: COSTOS VARIABLES
A13: % Costos Variables sobre Ventas: | B13: 0.37
A15: COSTOS FIJOS MENSUALES
A16: Salarios y Cargas Sociales: | B16: 3800000
A17: Alquileres: | B17: 1900000
A18: Servicios (luz, agua, internet): | B18: 300000
A19: Marketing y Publicidad: | B19: 500000
A20: Otros Gastos Fijos: | B20: 400000
A22: DEPRECIACIÓN
A23: Vida Útil Activos (años): | B23: 10
A24: Método Depreciación: | B24: Lineal
A26: FINANCIAMIENTO
A27: Monto del Préstamo: | B27: 4000000
A28: Tasa de Interés Anual: | B28: 0.07
A29: Plazo del Préstamo (meses): | B29: 60
A31: VALOR RESIDUAL
A32: % Valor Residual de Activos Fijos: | B32: 0.2

Sheet Ingresos
A1: PROYECCIÓN DE INGRESOS
A3: Concepto | B3: Mes 1 | C3: Mes 2 | D3: Mes 3 | E3: Mes 4 | F3: Mes 5 | G3: Mes 6 | H3: Mes 7 | I3: Mes 8 | J3: Mes 9 | K3: Mes 10 | L3: Mes 11 | M3: Mes 12 | N3: Mes 13 | O3: Mes 14 | P3: Mes 15 | Q3: Mes 16 | R3: Mes 17 | S3: Mes 18 | T3: Mes 19 | U3: Mes 20 | V3: Mes 21 | W3: Mes 22 | X3: Mes 23 | Y3: Mes 24 | Z3: Mes 25 | AA3: Mes 26 | AB3: Mes 27 | AC3: Mes 28 | AD3: Mes 29 | AE3: Mes 30 | AF3: Mes 31 | AG3: Mes 32 | AH3: Mes 33 | AI3: Mes 34 | AJ3: Mes 35 | AK3: Mes 36 | AL3: Mes 37 | AM3: Mes 38 | AN3: Mes 39 | AO3: Mes 40 | AP3: Mes 41 | AQ3: Mes 42 | AR3: Mes 43 | AS3: Mes 44 | AT3: Mes 45 | AU3: Mes 46 | AV3: Mes 47 | AW3: Mes 48 | AX3: Mes 49 | AY3: Mes 50 | AZ3: Mes 51 | BA3: Mes 52 | BB3: Mes 53 | BC3: Mes 54 | BD3: Mes 55 | BE3: Mes 56 | BF3: Mes 57 | BG3: Mes 58 | BH3: Mes 59 | BI3: Mes 60 | BJ3: Mes 61 | BK3: Mes 62 | BL3: Mes 63 | BM3: Mes 64 | BN3: Mes 65 | BO3: Mes 66 | BP3: Mes 67 | BQ3: Mes 68 | BR3: Mes 69 | BS3: Mes 70 | BT3: Mes 71 | BU3: Mes 72 | BV3: Mes 73 | BW3: Mes 74 | BX3: Mes 75 | BY3: Mes 76 | BZ3: Mes 77 | CA3: Mes 78 | CB3: Mes 79 | CC3: Mes 80 | CD3: Mes 81 | CE3: Mes 82 | CF3: Mes 83 | CG3: Mes 84 | CH3: Mes 85 | CI3: Mes 86 | CJ3: Mes 87 | CK3: Mes 88 | CL3: Mes 89 | CM3: Mes 90 | CN3: Mes 91 | CO3: Mes 92 | CP3: Mes 93 | CQ3: Mes 94 | CR3: Mes 95 | CS3: Mes 96 | CT3: Mes 97 | CU3: Mes 98 | CV3: Mes 99 | CW3: Mes 100 | CX3: Mes 101 | CY3: Mes 102 | CZ3: Mes 103 | DA3: Mes 104 | DB3: Mes 105 | DC3: Mes 106 | DD3: Mes 107 | DE3: Mes 108 | DF3: Mes 109 | DG3: Mes 110 | DH3: Mes 111 | DI3: Mes 112 | DJ3: Mes 113 | DK3: Mes 114 | DL3: Mes 115 | DM3: Mes 116 | DN3: Mes 117 | DO3: Mes 118 | DP3: Mes 119 | DQ3: Mes 120 | DR3: Mes 121 | DS3: Mes 122 | DT3: Mes 123 | DU3: Mes 124 | DV3: Mes 125 | DW3: Mes 126 | DX3: Mes 127 | DY3: Mes 128 | DZ3: Mes 129 | EA3: Mes 130 | EB3: Mes 131 | EC3: Mes 132 | ED3: Mes 133 | EE3: Mes 134 | EF3: Mes 135 | EG3: Mes 136 | EH3: Mes 137 | EI3: Mes 138 | EJ3: Mes 139 | EK3: Mes 140 | EL3: Mes 141 | EM3: Mes 142 | EN3: Mes 143 | EO3: Mes 144 | EP3: Mes 145 | EQ3: Mes 146 | ER3: Mes 147 | ES3: Mes 148 | ET3: Mes 149 | EU3: Mes 150 | EV3: Mes 151 | EW3: Mes 152 | EX3: Mes 153 | EY3: Mes 154 | EZ3: Mes 155 | FA3: Mes 156 | FB3: Mes 157 | FC3: Mes 158 | FD3: Mes 159 | FE3: Mes 160 | FF3: Mes 161 | FG3: Mes 162 | FH3: Mes 163 | FI3: Mes 164 | FJ3: Mes 165 | FK3: Mes 166 | FL3: Mes 167 | FM3: Mes 168 | FN3: Mes 169 | FO3: Mes 170 | FP3: Mes 171 | FQ3: Mes 172 | FR3: Mes 173 | FS3: Mes 174 | FT3: Mes 175 | FU3: Mes 176 | FV3: Mes 177 | FW3: Mes 178 | FX3: Mes 179 | FY3: Mes 180 | FZ3: Mes 181 | GA3: Mes 182 | GB3: Mes 183 | GC3: Mes 184 | GD3: Mes 185 | GE3: Mes 186 | GF3: Mes 187 | GG3: Mes 188 | GH3: Mes 189 | GI3: Mes 190 | GJ3: Mes 191 | GK3: Mes 192 | GL3: Mes 193 | GM3: Mes 194 | GN3: Mes 195 | GO3: Mes 196 | GP3: Mes 197 | GQ3: Mes 198 | GR3: Mes 199 | GS3: Mes 200 | GT3: Mes 201 | GU3: Mes 202 | GV3: Mes 203 | GW3: Mes 204 | GX3: Mes 205 | GY3: Mes 206 | GZ3: Mes 207 | HA3: Mes 208 | HB3: Mes 209 | HC3: Mes 210 | HD3: Mes 211 | HE3: Mes 212 | HF3: Mes 213 | HG3: Mes 214 | HH3: Mes 215 | HI3: Mes 216 | HJ3: Mes 217 | HK3: Mes 218 | HL3: Mes 219 | HM3: Mes 220 | HN3: Mes 221 | HO3: Mes 222 | HP3: Mes 223 | HQ3: Mes 224 | HR3: Mes 225 | HS3: Mes 226 | HT3: Mes 227 | HU3: Mes 228 | HV3: Mes 229 | HW3: Mes 230 | HX3: Mes 231 | HY3: Mes 232 | HZ3: Mes 233 | IA3: Mes 234 | IB3: Mes 235 | IC3: Mes 236 | ID3: Mes 237 | IE3: Mes 238 | IF3: Mes 239 | IG3: Mes 240 | IH3: Mes 241 | II3: Mes 242 | IJ3: Mes 243 | IK3: Mes 244 | IL3: Mes 245 | IM3: Mes 246 | IN3: Mes 247 | IO3: Mes 248 | IP3: Mes 249 | IQ3: Mes 250 | IR3: Mes 251 | IS3: Mes 252 | IT3: Mes 253 | IU3: Mes 254 | IV3: Mes 255 | IW3: Mes 256 | IX3: Mes 257 | IY3: Mes 258 | IZ3: Mes 259 | JA3: Mes 260 | JB3: Mes 261 | JC3: Mes 262 | JD3: Mes 263 | JE3: Mes 264 | JF3: Mes 265 | JG3: Mes 266 | JH3: Mes 267 | JI3: Mes 268 | JJ3: Mes 269 | JK3: Mes 270 | JL3: Mes 271 | JM3: Mes 272 | JN3: Mes 273 | JO3: Mes 274 | JP3: Mes 275 | JQ3: Mes 276 | JR3: Mes 277 | JS3: Mes 278 | JT3: Mes 279 | JU3: Mes 280 | JV3: Mes 281 | JW3: Mes 282 | JX3: Mes 283 | JY3: Mes 284 | JZ3: Mes 285 | KA3: Mes 286 | KB3: Mes 287 | KC3: Mes 288 | KD3: Mes 289 | KE3: Mes 290 | KF3: Mes 291 | KG3: Mes 292 | KH3: Mes 293 | KI3: Mes 294 | KJ3: Mes 295 | KK3: Mes 296 | KL3: Mes 297 | KM3: Mes 298 | KN3: Mes 299 | KO3: Mes 300
A4: Ingresos por Ventas | B4: =Supuestos!$B$9*POWER(1+Supuestos!$B$10,0) -> 10700000 | C4: =Supuestos!$B$9*POWER(1+Supuestos!$B$10,0) -> 10700000 | D4: =Supuestos!$B$9*POWER(1+Supuestos!$B$10,0) -> 10700000 | E4: =Supuestos!$B$9*POWER(1+Supuestos!$B$10,0) -> 10700000 | F4: =Supuestos!$B$9*POWER(1+Supuestos!$B$10,0) -> 10700000 | G4: =Supuestos!$B$9*POWER(1+Supuestos!$B$10,0) -> 10700000 | H4: =Supuestos!$B$9*POWER(1+Supuestos!$B$10,0) -> 10700000 | I4: =Supuestos!$B$9*POWER(1+Supuestos!$B$10,0) -> 10700000 | ... M4: =Supuestos!$B$9*POWER(1+Supuestos!$B$10,0) -> 10700000 | N4: =Supuestos!$B$9*POWER(1+Supuestos!$B$10,1) -> 11449000 | O4: =Supuestos!$B$9*POWER(1+Supuestos!$B$10,1) -> 11449000 | P4: =Supuestos!$B$9*POWER(1+Supuestos!$B$10,1) -> 11449000 | Q4: =Supuestos!$B$9*POWER(1+Supuestos!$B$10,1) -> 11449000 | R4: =Supuestos!$B$9*POWER(1+Supuestos!$B$10,1) -> 11449000 | S4: =Supuestos!$B$9*POWER(1+Supuestos!$B$10,1) -> 11449000 | T4: =Supuestos!$B$9*POWER(1+Supuestos!$B$10,1) -> 11449000 | U4: =Supuestos!$B$9*POWER(1+Supuestos!$B$10,1) -> 11449000 | ... Y4: =Supuestos!$B$9*POWER(1+Supuestos!$B$10,1) -> 11449000 | Z4: =Supuestos!$B$9*POWER(1+Supuestos!$B$10,2) -> 12250430 | AA4: =Supuestos!$B$9*POWER(1+Supuestos!$B$10,2) -> 12250430 | AB4: =Supuestos!$B$9*POWER(1+Supuestos!$B$10,2) -> 12250430 | AC4: =Supuestos!$B$9*POWER(1+Supuestos!$B$10,2) -> 12250430 | AD4: =Supuestos!$B$9*POWER(1+Supuestos!$B$10,2) -> 12250430 | AE4: =Supuestos!$B$9*POWER(1+Supuestos!$B$10,2) -> 12250430 | AF4: =Supuestos!$B$9*POWER(1+Supuestos!$B$10,2) -> 12250430 | AG4: =Supuestos!$B$9*POWER(1+Supuestos!$B$10,2) -> 12250430 | ... AK4: =Supuestos!$B$9*POWER(1+Supuestos!$B$10,2) -> 12250430 | AL4: =Supuestos!$B$9*POWER(1+Supuestos!$B$10,3) -> 13107960 | AM4: =Supuestos!$B$9*POWER(1+Supuestos!$B$10,3) -> 13107960 | AN4: =Supuestos!$B$9*POWER(1+Supuestos!$B$10,3) -> 13107960 | AO4: =Supuestos!$B$9*POWER(1+Supuestos!$B$10,3) -> 13107960 | AP4: =Supuestos!$B$9*POWER(1+Supuestos!$B$10,3) -> 13107960 | AQ4: =Supuestos!$B$9*POWER(1+Supuestos!$B$10,3) -> 13107960 | AR4: =Supuestos!$B$9*POWER(1+Supuestos!$B$10,3) -> 13107960 | AS4: =Supuestos!$B$9*POWER(1+Supuestos!$B$10,3) -> 13107960 | ... AW4: =Supuestos!$B$9*POWER(1+Supuestos!$B$10,3) -> 13107960 | AX4: =Supuestos!$B$9*POWER(1+Supuestos!$B$10,4) -> 14025517 | AY4: =Supuestos!$B$9*POWER(1+Supuestos!$B$10,4) -> 14025517 | AZ4: =Supuestos!$B$9*POWER(1+Supuestos!$B$10,4) -> 14025517 | BA4: =Supuestos!$B$9*POWER(1+Supuestos!$B$10,4) -> 14025517 | BB4: =Supuestos!$B$9*POWER(1+Supuestos!$B$10,4) -> 14025517 | BC4: =Supuestos!$B$9*POWER(1+Supuestos!$B$10,4) -> 14025517 | BD4: =Supuestos!$B$9*POWER(1+Supuestos!$B$10,4) -> 14025517 | BE4: =Supuestos!$B$9*POWER(1+Supuestos!$B$10,4) -> 14025517 | ... BI4: =Supuestos!$B$9*POWER(1+Supuestos!$B$10,4) -> 14025517 | BJ4: =Supuestos!$B$9*POWER(1+Supuestos!$B$10,5) -> 15007304 | BK4: =Supuestos!$B$9*POWER(1+Supuestos!$B$10,5) -> 15007304 | BL4: =Supuestos!$B$9*POWER(1+Supuestos!$B$10,5) -> 15007304 | BM4: =Supuestos!$B$9*POWER(1+Supuestos!$B$10,5) -> 15007304 | BN4: =Supuestos!$B$9*POWER(1+Supuestos!$B$10,5) -> 15007304 | BO4: =Supuestos!$B$9*POWER(1+Supuestos!$B$10,5) -> 15007304 | BP4: =Supuestos!$B$9*POWER(1+Supuestos!$B$10,5) -> 15007304 | BQ4: =Supuestos!$B$9*POWER(1+Supuestos!$B$10,5) -> 15007304 | ... BU4: =Supuestos!$B$9*POWER(1+Supuestos!$B$10,5) -> 15007304 | BV4: =Supuestos!$B$9*POWER(1+Supuestos!$B$10,6) -> 16057815 | BW4: =Supuestos!$B$9*POWER(1+Supuestos!$B$10,6) -> 16057815 | BX4: =Supuestos!$B$9*POWER(1+Supuestos!$B$10,6) -> 16057815 | BY4: =Supuestos!$B$9*POWER(1+Supuestos!$B$10,6) -> 16057815 | BZ4: =Supuestos!$B$9*POWER(1+Supuestos!$B$10,6) -> 16057815 | CA4: =Supuestos!$B$9*POWER(1+Supuestos!$B$10,6) -> 16057815 | CB4: =Supuestos!$B$9*POWER(1+Supuestos!$B$10,6) -> 16057815 | CC4: =Supuestos!$B$9*POWER(1+Supuestos!$B$10,6) -> 16057815 | ... CG4: =Supuestos!$B$9*POWER(1+Supuestos!$B$10,6) -> 16057815 | CH4: =Supuestos!$B$9*POWER(1+Supuestos!$B$10,7) -> 17181862 | CI4: =Supuestos!$B$9*POWER(1+Supuestos!$B$10,7) -> 17181862 | CJ4: =Supuestos!$B$9*POWER(1+Supuestos!$B$10,7) -> 17181862 | CK4: =Supuestos!$B$9*POWER(1+Supuestos!$B$10,7) -> 17181862 | CL4: =Supuestos!$B$9*POWER(1+Supuestos!$B$10,7) -> 17181862 | CM4: =Supuestos!$B$9*POWER(1+Supuestos!$B$10,7) -> 17181862 | CN4: =Supuestos!$B$9*POWER(1+Supuestos!$B$10,7) -> 17181862 | CO4: =Supuestos!$B$9*POWER(1+Supuestos!$B$10,7) -> 17181862 | ... CS4: =Supuestos!$B$9*POWER(1+Supuestos!$B$10,7) -> 17181862 | CT4: =Supuestos!$B$9*POWER(1+Supuestos!$B$10,8) -> 18384592 | CU4: =Supuestos!$B$9*POWER(1+Supuestos!$B$10,8) -> 18384592 | CV4: =Supuestos!$B$9*POWER(1+Supuestos!$B$10,8) -> 18384592 | CW4: =Supuestos!$B$9*POWER(1+Supuestos!$B$10,8) -> 18384592 | CX4: =Supuestos!$B$9*POWER(1+Supuestos!$B$10,8) -> 18384592 | CY4: =Supuestos!$B$9*POWER(1+Supuestos!$B$10,8) -> 18384592 | CZ4: =Supuestos!$B$9*POWER(1+Supuestos!$B$10,8) -> 18384592 | DA4: =Supuestos!$B$9*POWER(1+Supuestos!$B$10,8) -> 18384592 | ... DE4: =Supuestos!$B$9*POWER(1+Supuestos!$B$10,8) -> 18384592 | DF4: =Supuestos!$B$9*POWER(1+Supuestos!$B$10,9) -> 19671514 | DG4: =Supuestos!$B$9*POWER(1+Supuestos!$B$10,9) -> 19671514 | DH4: =Supuestos!$B$9*POWER(1+Supuestos!$B$10,9) -> 19671514 | DI4: =Supuestos!$B$9*POWER(1+Supuestos!$B$10,9) -> 19671514 | DJ4: =Supuestos!$B$9*POWER(1+Supuestos!$B$10,9) -> 19671514 | DK4: =Supuestos!$B$9*POWER(1+Supuestos!$B$10,9) -> 19671514 | DL4: =Supuestos!$B$9*POWER(1+Supuestos!$B$10,9) -> 19671514 | DM4: =Supuestos!$B$9*POWER(1+Supuestos!$B$10,9) -> 19671514 | ... DQ4: =Supuestos!$B$9*POWER(1+Supuestos!$B$10,9) -> 19671514 | DR4: =Supuestos!$B$9*POWER(1+Supuestos!$B$10,10) -> 21048520 | DS4: =Supuestos!$B$9*POWER(1+Supuestos!$B$10,10) -> 21048520 | DT4: =Supuestos!$B$9*POWER(1+Supuestos!$B$10,10) -> 21048520 | DU4: =Supuestos!$B$9*POWER(1+Supuestos!$B$10,10) -> 21048520 | DV4: =Supuestos!$B$9*POWER(1+Supuestos!$B$10,10) -> 21048520 | DW4: =Supuestos!$B$9*POWER(1+Supuestos!$B$10,10) -> 21048520 | DX4: =Supuestos!$B$9*POWER(1+Supuestos!$B$10,10) -> 21048520 | DY4: =Supuestos!$B$9*POWER(1+Supuestos!$B$10,10) -> 21048520 | ... EC4: =Supuestos!$B$9*POWER(1+Supuestos!$B$10,10) -> 21048520 | ED4: =Supuestos!$B$9*POWER(1+Supuestos!$B$10,11) -> 22521916 | EE4: =Supuestos!$B$9*POWER(1+Supuestos!$B$10,11) -> 22521916 | EF4: =Supuestos!$B$9*POWER(1+Supuestos!$B$10,11) -> 22521916 | EG4: =Supuestos!$B$9*POWER(1+Supuestos!$B$10,11) -> 22521916 | EH4: =Supuestos!$B$9*POWER(1+Supuestos!$B$10,11) -> 22521916 | EI4: =Supuestos!$B$9*POWER(1+Supuestos!$B$10,11) -> 22521916 | EJ4: =Supuestos!$B$9*POWER(1+Supuestos!$B$10,11) -> 22521916 | EK4: =Supuestos!$B$9*POWER(1+Supuestos!$B$10,11) -> 22521916 | ... EO4: =Supuestos!$B$9*POWER(1+Supuestos!$B$10,11) -> 22521916 | EP4: =Supuestos!$B$9*POWER(1+Supuestos!$B$10,12) -> 24098450 | EQ4: =Supuestos!$B$9*POWER(1+Supuestos!$B$10,12) -> 24098450 | ER4: =Supuestos!$B$9*POWER(1+Supuestos!$B$10,12) -> 24098450 | ES4: =Supuestos!$B$9*POWER(1+Supuestos!$B$10,12) -> 24098450 | ET4: =Supuestos!$B$9*POWER(1+Supuestos!$B$10,12) -> 24098450 | EU4: =Supuestos!$B$9*POWER(1+Supuestos!$B$10,12) -> 24098450 | EV4: =Supuestos!$B$9*POWER(1+Supuestos!$B$10,12) -> 24098450 | EW4: =Supuestos!$B$9*POWER(1+Supuestos!$B$10,12) -> 24098450 | ... FA4: =Supuestos!$B$9*POWER(1+Supuestos!$B$10,12) -> 24098450 | FB4: =Supuestos!$B$9*POWER(1+Supuestos!$B$10,13) -> 25785342 | FC4: =Supuestos!$B$9*POWER(1+Supuestos!$B$10,13) -> 25785342 | FD4: =Supuestos!$B$9*POWER(1+Supuestos!$B$10,13) -> 25785342 | FE4: =Supuestos!$B$9*POWER(1+Supuestos!$B$10,13) -> 25785342 | FF4: =Supuestos!$B$9*POWER(1+Supuestos!$B$10,13) -> 25785342 | FG4: =Supuestos!$B$9*POWER(1+Supuestos!$B$10,13) -> 25785342 | FH4: =Supuestos!$B$9*POWER(1+Supuestos!$B$10,13) -> 25785342 | FI4: =Supuestos!$B$9*POWER(1+Supuestos!$B$10,13) -> 25785342 | ... FM4: =Supuestos!$B$9*POWER(1+Supuestos!$B$10,13) -> 25785342 | FN4: =Supuestos!$B$9*POWER(1+Supuestos!$B$10,14) -> 27590315 | FO4: =Supuestos!$B$9*POWER(1+Supuestos!$B$10,14) -> 27590315 | FP4: =Supuestos!$B$9*POWER(1+Supuestos!$B$10,14) -> 27590315 | FQ4: =Supuestos!$B$9*POWER(1+Supuestos!$B$10,14) -> 27590315 | FR4: =Supuestos!$B$9*POWER(1+Supuestos!$B$10,14) -> 27590315 | FS4: =Supuestos!$B$9*POWER(1+Supuestos!$B$10,14) -> 27590315 | FT4: =Supuestos!$B$9*POWER(1+Supuestos!$B$10,14) -> 27590315 | FU4: =Supuestos!$B$9*POWER(1+Supuestos!$B$10,14) -> 27590315 | ... FY4: =Supuestos!$B$9*POWER(1+Supuestos!$B$10,14) -> 27590315 | FZ4: =Supuestos!$B$9*POWER(1+Supuestos!$B$10,15) -> 29521637 | GA4: =Supuestos!$B$9*POWER(1+Supuestos!$B$10,15) -> 29521637 | GB4: =Supuestos!$B$9*POWER(1+Supuestos!$B$10,15) -> 29521637 | GC4: =Supuestos!$B$9*POWER(1+Supuestos!$B$10,15) -> 29521637 | GD4: =Supuestos!$B$9*POWER(1+Supuestos!$B$10,15) -> 29521637 | GE4: =Supuestos!$B$9*POWER(1+Supuestos!$B$10,15) -> 29521637 | GF4: =Supuestos!$B$9*POWER(1+Supuestos!$B$10,15) -> 29521637 | GG4: =Supuestos!$B$9*POWER(1+Supuestos!$B$10,15) -> 29521637 | ... GK4: =Supuestos!$B$9*POWER(1+Supuestos!$B$10,15) -> 29521637 | GL4: =Supuestos!$B$9*POWER(1+Supuestos!$B$10,16) -> 31588152 | GM4: =Supuestos!$B$9*POWER(1+Supuestos!$B$10,16) -> 31588152 | GN4: =Supuestos!$B$9*POWER(1+Supuestos!$B$10,16) -> 31588152 | GO4: =Supuestos!$B$9*POWER(1+Supuestos!$B$10,16) -> 31588152 | GP4: =Supuestos!$B$9*POWER(1+Supuestos!$B$10,16) -> 31588152 | GQ4: =Supuestos!$B$9*POWER(1+Supuestos!$B$10,16) -> 31588152 | GR4: =Supuestos!$B$9*POWER(1+Supuestos!$B$10,16) -> 31588152 | GS4: =Supuestos!$B$9*POWER(1+Supuestos!$B$10,16) -> 31588152 | ... GW4: =Supuestos!$B$9*POWER(1+Supuestos!$B$10,16) -> 31588152 | GX4: =Supuestos!$B$9*POWER(1+Supuestos!$B$10,17) -> 33799323 | GY4: =Supuestos!$B$9*POWER(1+Supuestos!$B$10,17) -> 33799323 | GZ4: =Supuestos!$B$9*POWER(1+Supuestos!$B$10,17) -> 33799323 | HA4: =Supuestos!$B$9*POWER(1+Supuestos!$B$10,17) -> 33799323 | HB4: =Supuestos!$B$9*POWER(1+Supuestos!$B$10,17) -> 33799323 | HC4: =Supuestos!$B$9*POWER(1+Supuestos!$B$10,17) -> 33799323 | HD4: =Supuestos!$B$9*POWER(1+Supuestos!$B$10,17) -> 33799323 | HE4: =Supuestos!$B$9*POWER(1+Supuestos!$B$10,17) -> 33799323 | ... HI4: =Supuestos!$B$9*POWER(1+Supuestos!$B$10,17) -> 33799323 | HJ4: =Supuestos!$B$9*POWER(1+Supuestos!$B$10,18) -> 36165275 | HK4: =Supuestos!$B$9*POWER(1+Supuestos!$B$10,18) -> 36165275 | HL4: =Supuestos!$B$9*POWER(1+Supuestos!$B$10,18) -> 36165275 | HM4: =Supuestos!$B$9*POWER(1+Supuestos!$B$10,18) -> 36165275 | HN4: =Supuestos!$B$9*POWER(1+Supuestos!$B$10,18) -> 36165275 | HO4: =Supuestos!$B$9*POWER(1+Supuestos!$B$10,18) -> 36165275 | HP4: =Supuestos!$B$9*POWER(1+Supuestos!$B$10,18) -> 36165275 | HQ4: =Supuestos!$B$9*POWER(1+Supuestos!$B$10,18) -> 36165275 | ... HU4: =Supuestos!$B$9*POWER(1+Supuestos!$B$10,18) -> 36165275 | HV4: =Supuestos!$B$9*POWER(1+Supuestos!$B$10,19) -> 38696845 | HW4: =Supuestos!$B$9*POWER(1+Supuestos!$B$10,19) -> 38696845 | HX4: =Supuestos!$B$9*POWER(1+Supuestos!$B$10,19) -> 38696845 | HY4: =Supuestos!$B$9*POWER(1+Supuestos!$B$10,19) -> 38696845 | HZ4: =Supuestos!$B$9*POWER(1+Supuestos!$B$10,19) -> 38696845 | IA4: =Supuestos!$B$9*POWER(1+Supuestos!$B$10,19) -> 38696845 | IB4: =Supuestos!$B$9*POWER(1+Supuestos!$B$10,19) -> 38696845 | IC4: =Supuestos!$B$9*POWER(1+Supuestos!$B$10,19) -> 38696845 | ... IG4: =Supuestos!$B$9*POWER(1+Supuestos!$B$10,19) -> 38696845 | IH4: =Supuestos!$B$9*POWER(1+Supuestos!$B$10,20) -> 41405624 | II4: =Supuestos!$B$9*POWER(1+Supuestos!$B$10,20) -> 41405624 | IJ4: =Supuestos!$B$9*POWER(1+Supuestos!$B$10,20) -> 41405624 | IK4: =Supuestos!$B$9*POWER(1+Supuestos!$B$10,20) -> 41405624 | IL4: =Supuestos!$B$9*POWER(1+Supuestos!$B$10,20) -> 41405624 | IM4: =Supuestos!$B$9*POWER(1+Supuestos!$B$10,20) -> 41405624 | IN4: =Supuestos!$B$9*POWER(1+Supuestos!$B$10,20) -> 41405624 | IO4: =Supuestos!$B$9*POWER(1+Supuestos!$B$10,20) -> 41405624 | ... IS4: =Supuestos!$B$9*POWER(1+Supuestos!$B$10,20) -> 41405624 | IT4: =Supuestos!$B$9*POWER(1+Supuestos!$B$10,21) -> 44304017 | IU4: =Supuestos!$B$9*POWER(1+Supuestos!$B$10,21) -> 44304017 | IV4: =Supuestos!$B$9*POWER(1+Supuestos!$B$10,21) -> 44304017 | IW4: =Supuestos!$B$9*POWER(1+Supuestos!$B$10,21) -> 44304017 | IX4: =Supuestos!$B$9*POWER(1+Supuestos!$B$10,21) -> 44304017 | IY4: =Supuestos!$B$9*POWER(1+Supuestos!$B$10,21) -> 44304017 | IZ4: =Supuestos!$B$9*POWER(1+Supuestos!$B$10,21) -> 44304017 | JA4: =Supuestos!$B$9*POWER(1+Supuestos!$B$10,21) -> 44304017 | ... JE4: =Supuestos!$B$9*POWER(1+Supuestos!$B$10,21) -> 44304017 | JF4: =Supuestos!$B$9*POWER(1+Supuestos!$B$10,22) -> 47405299 | JG4: =Supuestos!$B$9*POWER(1+Supuestos!$B$10,22) -> 47405299 | JH4: =Supuestos!$B$9*POWER(1+Supuestos!$B$10,22) -> 47405299 | JI4: =Supuestos!$B$9*POWER(1+Supuestos!$B$10,22) -> 47405299 | JJ4: =Supuestos!$B$9*POWER(1+Supuestos!$B$10,22) -> 47405299 | JK4: =Supuestos!$B$9*POWER(1+Supuestos!$B$10,22) -> 47405299 | JL4: =Supuestos!$B$9*POWER(1+Supuestos!$B$10,22) -> 47405299 | JM4: =Supuestos!$B$9*POWER(1+Supuestos!$B$10,22) -> 47405299 | ... JQ4: =Supuestos!$B$9*POWER(1+Supuestos!$B$10,22) -> 47405299 | JR4: =Supuestos!$B$9*POWER(1+Supuestos!$B$10,23) -> 50723670 | JS4: =Supuestos!$B$9*POWER(1+Supuestos!$B$10,23) -> 50723670 | JT4: =Supuestos!$B$9*POWER(1+Supuestos!$B$10,23) -> 50723670 | JU4: =Supuestos!$B$9*POWER(1+Supuestos!$B$10,23) -> 50723670 | JV4: =Supuestos!$B$9*POWER(1+Supuestos!$B$10,23) -> 50723670 | JW4: =Supuestos!$B$9*POWER(1+Supuestos!$B$10,23) -> 50723670 | JX4: =Supuestos!$B$9*POWER(1+Supuestos!$B$10,23) -> 50723670 | JY4: =Supuestos!$B$9*POWER(1+Supuestos!$B$10,23) -> 50723670 | ... KC4: =Supuestos!$B$9*POWER(1+Supuestos!$B$10,23) -> 50723670 | KD4: =Supuestos!$B$9*POWER(1+Supuestos!$B$10,24) -> 54274326 | KE4: =Supuestos!$B$9*POWER(1+Supuestos!$B$10,24) -> 54274326 | KF4: =Supuestos!$B$9*POWER(1+Supuestos!$B$10,24) -> 54274326 | KG4: =Supuestos!$B$9*POWER(1+Supuestos!$B$10,24) -> 54274326 | KH4: =Supuestos!$B$9*POWER(1+Supuestos!$B$10,24) -> 54274326 | KI4: =Supuestos!$B$9*POWER(1+Supuestos!$B$10,24) -> 54274326 | KJ4: =Supuestos!$B$9*POWER(1+Supuestos!$B$10,24) -> 54274326 | KK4: =Supuestos!$B$9*POWER(1+Supuestos!$B$10,24) -> 54274326 | ... KO4: =Supuestos!$B$9*POWER(1+Supuestos!$B$10,24) -> 54274326
A5: Otros Ingresos | B5: 0 | C5: 0 | D5: 0 | E5: 0 | F5: 0 | G5: 0 | H5: 0 | I5: 0 | J5: 0 | K5: 0 | L5: 0 | M5: 0 | N5: 0 | O5: 0 | P5: 0 | Q5: 0 | R5: 0 | S5: 0 | T5: 0 | U5: 0 | V5: 0 | W5: 0 | X5: 0 | Y5: 0 | Z5: 0 | AA5: 0 | AB5: 0 | AC5: 0 | AD5: 0 | AE5: 0 | AF5: 0 | AG5: 0 | AH5: 0 | AI5: 0 | AJ5: 0 | AK5: 0 | AL5: 0 | AM5: 0 | AN5: 0 | AO5: 0 | AP5: 0 | AQ5: 0 | AR5: 0 | AS5: 0 | AT5: 0 | AU5: 0 | AV5: 0 | AW5: 0 | AX5: 0 | AY5: 0 | AZ5: 0 | BA5: 0 | BB5: 0 | BC5: 0 | BD5: 0 | BE5: 0 | BF5: 0 | BG5: 0 | BH5: 0 | BI5: 0 | BJ5: 0 | BK5: 0 | BL5: 0 | BM5: 0 | BN5: 0 | BO5: 0 | BP5: 0 | BQ5: 0 | BR5: 0 | BS5: 0 | BT5: 0 | BU5: 0 | BV5: 0 | BW5: 0 | BX5: 0 | BY5: 0 | BZ5: 0 | CA5: 0 | CB5: 0 | CC5: 0 | CD5: 0 | CE5: 0 | CF5: 0 | CG5: 0 | CH5: 0 | CI5: 0 | CJ5: 0 | CK5: 0 | CL5: 0 | CM5: 0 | CN5: 0 | CO5: 0 | CP5: 0 | CQ5: 0 | CR5: 0 | CS5: 0 | CT5: 0 | CU5: 0 | CV5: 0 | CW5: 0 | CX5: 0 | CY5: 0 | CZ5: 0 | DA5: 0 | DB5: 0 | DC5: 0 | DD5: 0 | DE5: 0 | DF5: 0 | DG5: 0 | DH5: 0 | DI5: 0 | DJ5: 0 | DK5: 0 | DL5: 0 | DM5: 0 | DN5: 0 | DO5: 0 | DP5: 0 | DQ5: 0 | DR5: 0 | DS5: 0 | DT5: 0 | DU5: 0 | DV5: 0 | DW5: 0 | DX5: 0 | DY5: 0 | DZ5: 0 | EA5: 0 | EB5: 0 | EC5: 0 | ED5: 0 | EE5: 0 | EF5: 0 | EG5: 0 | EH5: 0 | EI5: 0 | EJ5: 0 | EK5: 0 | EL5: 0 | EM5: 0 | EN5: 0 | EO5: 0 | EP5: 0 | EQ5: 0 | ER5: 0 | ES5: 0 | ET5: 0 | EU5: 0 | EV5: 0 | EW5: 0 | EX5: 0 | EY5: 0 | EZ5: 0 | FA5: 0 | FB5: 0 | FC5: 0 | FD5: 0 | FE5: 0 | FF5: 0 | FG5: 0 | FH5: 0 | FI5: 0 | FJ5: 0 | FK5: 0 | FL5: 0 | FM5: 0 | FN5: 0 | FO5: 0 | FP5: 0 | FQ5: 0 | FR5: 0 | FS5: 0 | FT5: 0 | FU5: 0 | FV5: 0 | FW5: 0 | FX5: 0 | FY5: 0 | FZ5: 0 | GA5: 0 | GB5: 0 | GC5: 0 | GD5: 0 | GE5: 0 | GF5: 0 | GG5: 0 | GH5: 0 | GI5: 0 | GJ5: 0 | GK5: 0 | GL5: 0 | GM5: 0 | GN5: 0 | GO5: 0 | GP5: 0 | GQ5: 0 | GR5: 0 | GS5: 0 | GT5: 0 | GU5: 0 | GV5: 0 | GW5: 0 | GX5: 0 | GY5: 0 | GZ5: 0 | HA5: 0 | HB5: 0 | HC5: 0 | HD5: 0 | HE5: 0 | HF5: 0 | HG5: 0 | HH5: 0 | HI5: 0 | HJ5: 0 | HK5: 0 | HL5: 0 | HM5: 0 | HN5: 0 | HO5: 0 | HP5: 0 | HQ5: 0 | HR5: 0 | HS5: 0 | HT5: 0 | HU5: 0 | HV5: 0 | HW5: 0 | HX5: 0 | HY5: 0 | HZ5: 0 | IA5: 0 | IB5: 0 | IC5: 0 | ID5: 0 | IE5: 0 | IF5: 0 | IG5: 0 | IH5: 0 | II5: 0 | IJ5: 0 | IK5: 0 | IL5: 0 | IM5: 0 | IN5: 0 | IO5: 0 | IP5: 0 | IQ5: 0 | IR5: 0 | IS5: 0 | IT5: 0 | IU5: 0 | IV5: 0 | IW5: 0 | IX5: 0 | IY5: 0 | IZ5: 0 | JA5: 0 | JB5: 0 | JC5: 0 | JD5: 0 | JE5: 0 | JF5: 0 | JG5: 0 | JH5: 0 | JI5: 0 | JJ5: 0 | JK5: 0 | JL5: 0 | JM5: 0 | JN5: 0 | JO5: 0 | JP5: 0 | JQ5: 0 | JR5: 0 | JS5: 0 | JT5: 0 | JU5: 0 | JV5: 0 | JW5: 0 | JX5: 0 | JY5: 0 | JZ5: 0 | KA5: 0 | KB5: 0 | KC5: 0 | KD5: 0 | KE5: 0 | KF5: 0 | KG5: 0 | KH5: 0 | KI5: 0 | KJ5: 0 | KK5: 0 | KL5: 0 | KM5: 0 | KN5: 0 | KO5: 0
A6: TOTAL INGRESOS | B6: =B4+B5 -> 10700000 | C6: =C4+C5 -> 10700000 | D6: =D4+D5 -> 10700000 | E6: =E4+E5 -> 10700000 | F6: =F4+F5 -> 10700000 | G6: =G4+G5 -> 10700000 | H6: =H4+H5 -> 10700000 | I6: =I4+I5 -> 10700000 | ... KO6: =KO4+KO5 -> 54274326

Sheet Costos
A1: PROYECCIÓN DE COSTOS
A3: Concepto | B3: Mes 1 | C3: Mes 2 | D3: Mes 3 | E3: Mes 4 | F3: Mes 5 | G3: Mes 6 | H3: Mes 7 | I3: Mes 8 | J3: Mes 9 | K3: Mes 10 | L3: Mes 11 | M3: Mes 12 | N3: Mes 13 | O3: Mes 14 | P3: Mes 15 | Q3: Mes 16 | R3: Mes 17 | S3: Mes 18 | T3: Mes 19 | U3: Mes 20 | V3: Mes 21 | W3: Mes 22 | X3: Mes 23 | Y3: Mes 24 | Z3: Mes 25 | AA3: Mes 26 | AB3: Mes 27 | AC3: Mes 28 | AD3: Mes 29 | AE3: Mes 30 | AF3: Mes 31 | AG3: Mes 32 | AH3: Mes 33 | AI3: Mes 34 | AJ3: Mes 35 | AK3: Mes 36 | AL3: Mes 37 | AM3: Mes 38 | AN3: Mes 39 | AO3: Mes 40 | AP3: Mes 41 | AQ3: Mes 42 | AR3: Mes 43 | AS3: Mes 44 | AT3: Mes 45 | AU3: Mes 46 | AV3: Mes 47 | AW3: Mes 48 | AX3: Mes 49 | AY3: Mes 50 | AZ3: Mes 51 | BA3: Mes 52 | BB3: Mes 53 | BC3: Mes 54 | BD3: Mes 55 | BE3: Mes 56 | BF3: Mes 57 | BG3: Mes 58 | BH3: Mes 59 | BI3: Mes 60 | BJ3: Mes 61 | BK3: Mes 62 | BL3: Mes 63 | BM3: Mes 64 | BN3: Mes 65 | BO3: Mes 66 | BP3: Mes 67 | BQ3: Mes 68 | BR3: Mes 69 | BS3: Mes 70 | BT3: Mes 71 | BU3: Mes 72 | BV3: Mes 73 | BW3: Mes 74 | BX3: Mes 75 | BY3: Mes 76 | BZ3: Mes 77 | CA3: Mes 78 | CB3: Mes 79 | CC3: Mes 80 | CD3: Mes 81 | CE3: Mes 82 | CF3: Mes 83 | CG3: Mes 84 | CH3: Mes 85 | CI3: Mes 86 | CJ3: Mes 87 | CK3: Mes 88 | CL3: Mes 89 | CM3: Mes 90 | CN3: Mes 91 | CO3: Mes 92 | CP3: Mes 93 | CQ3: Mes 94 | CR3: Mes 95 | CS3: Mes 96 | CT3: Mes 97 | CU3: Mes 98 | CV3: Mes 99 | CW3: Mes 100 | CX3: Mes 101 | CY3: Mes 102 | CZ3: Mes 103 | DA3: Mes 104 | DB3: Mes 105 | DC3: Mes 106 | DD3: Mes 107 | DE3: Mes 108 | DF3: Mes 109 | DG3: Mes 110 | DH3: Mes 111 | DI3: Mes 112 | DJ3: Mes 113 | DK3: Mes 114 | DL3: Mes 115 | DM3: Mes 116 | DN3: Mes 117 | DO3: Mes 118 | DP3: Mes 119 | DQ3: Mes 120 | DR3: Mes 121 | DS3: Mes 122 | DT3: Mes 123 | DU3: Mes 124 | DV3: Mes 125 | DW3: Mes 126 | DX3: Mes 127 | DY3: Mes 128 | DZ3: Mes 129 | EA3: Mes 130 | EB3: Mes 131 | EC3: Mes 132 | ED3: Mes 133 | EE3: Mes 134 | EF3: Mes 135 | EG3: Mes 136 | EH3: Mes 137 | EI3: Mes 138 | EJ3: Mes 139 | EK3: Mes 140 | EL3: Mes 141 | EM3: Mes 142 | EN3: Mes 143 | EO3: Mes 144 | EP3: Mes 145 | EQ3: Mes 146 | ER3: Mes 147 | ES3: Mes 148 | ET3: Mes 149 | EU3: Mes 150 | EV3: Mes 151 | EW3: Mes 152 | EX3: Mes 153 | EY3: Mes 154 | EZ3: Mes 155 | FA3: Mes 156 | FB3: Mes 157 | FC3: Mes 158 | FD3: Mes 159 | FE3: Mes 160 | FF3: Mes 161 | FG3: Mes 162 | FH3: Mes 163 | FI3: Mes 164 | FJ3: Mes 165 | FK3: Mes 166 | FL3: Mes 167 | FM3: Mes 168 | FN3: Mes 169 | FO3: Mes 170 | FP3: Mes 171 | FQ3: Mes 172 | FR3: Mes 173 | FS3: Mes 174 | FT3: Mes 175 | FU3: Mes 176 | FV3: Mes 177 | FW3: Mes 178 | FX3: Mes 179 | FY3: Mes 180 | FZ3: Mes 181 | GA3: Mes 182 | GB3: Mes 183 | GC3: Mes 184 | GD3: Mes 185 | GE3: Mes 186 | GF3: Mes 187 | GG3: Mes 188 | GH3: Mes 189 | GI3: Mes 190 | GJ3: Mes 191 | GK3: Mes 192 | GL3: Mes 193 | GM3: Mes 194 | GN3: Mes 195 | GO3: Mes 196 | GP3: Mes 197 | GQ3: Mes 198 | GR3: Mes 199 | GS3: Mes 200 | GT3: Mes 201 | GU3: Mes 202 | GV3: Mes 203 | GW3: Mes 204 | GX3: Mes 205 | GY3: Mes 206 | GZ3: Mes 207 | HA3: Mes 208 | HB3: Mes 209 | HC3: Mes 210 | HD3: Mes 211 | HE3: Mes 212 | HF3: Mes 213 | HG3: Mes 214 | HH3: Mes 215 | HI3: Mes 216 | HJ3: Mes 217 | HK3: Mes 218 | HL3: Mes 219 | HM3: Mes 220 | HN3: Mes 221 | HO3: Mes 222 | HP3: Mes 223 | HQ3: Mes 224 | HR3: Mes 225 | HS3: Mes 226 | HT3: Mes 227 | HU3: Mes 228 | HV3: Mes 229 | HW3: Mes 230 | HX3: Mes 231 | HY3: Mes 232 | HZ3: Mes 233 | IA3: Mes 234 | IB3: Mes 235 | IC3: Mes 236 | ID3: Mes 237 | IE3: Mes 238 | IF3: Mes 239 | IG3: Mes 240 | IH3: Mes 241 | II3: Mes 242 | IJ3: Mes 243 | IK3: Mes 244 | IL3: Mes 245 | IM3: Mes 246 | IN3: Mes 247 | IO3: Mes 248 | IP3: Mes 249 | IQ3: Mes 250 | IR3: Mes 251 | IS3: Mes 252 | IT3: Mes 253 | IU3: Mes 254 | IV3: Mes 255 | IW3: Mes 256 | IX3: Mes 257 | IY3: Mes 258 | IZ3: Mes 259 | JA3: Mes 260 | JB3: Mes 261 | JC3: Mes 262 | JD3: Mes 263 | JE3: Mes 264 | JF3: Mes 265 | JG3: Mes 266 | JH3: Mes 267 | JI3: Mes 268 | JJ3: Mes 269 | JK3: Mes 270 | JL3: Mes 271 | JM3: Mes 272 | JN3: Mes 273 | JO3: Mes 274 | JP3: Mes 275 | JQ3: Mes 276 | JR3: Mes 277 | JS3: Mes 278 | JT3: Mes 279 | JU3: Mes 280 | JV3: Mes 281 | JW3: Mes 282 | JX3: Mes 283 | JY3: Mes 284 | JZ3: Mes 285 | KA3: Mes 286 | KB3: Mes 287 | KC3: Mes 288 | KD3: Mes 289 | KE3: Mes 290 | KF3: Mes 291 | KG3: Mes 292 | KH3: Mes 293 | KI3: Mes 294 | KJ3: Mes 295 | KK3: Mes 296 | KL3: Mes 297 | KM3: Mes 298 | KN3: Mes 299 | KO3: Mes 300
A4: COSTOS VARIABLES
A5: Costo de Ventas | B5: =Ingresos!B6*Supuestos!$B$13 -> 3959000 | C5: =Ingresos!C6*Supuestos!$B$13 -> 3959000 | D5: =Ingresos!D6*Supuestos!$B$13 -> 3959000 | E5: =Ingresos!E6*Supuestos!$B$13 -> 3959000 | F5: =Ingresos!F6*Supuestos!$B$13 -> 3959000 | G5: =Ingresos!G6*Supuestos!$B$13 -> 3959000 | H5: =Ingresos!H6*Supuestos!$B$13 -> 3959000 | I5: =Ingresos!I6*Supuestos!$B$13 -> 3959000 | ... KO5: =Ingresos!KO6*Supuestos!$B$13 -> 20081501
A6: Total Costos Variables | B6: =B5 -> 3959000 | C6: =C5 -> 3959000 | D6: =D5 -> 3959000 | E6: =E5 -> 3959000 | F6: =F5 -> 3959000 | G6: =G5 -> 3959000 | H6: =H5 -> 3959000 | I6: =I5 -> 3959000 | ... KO6: =KO5 -> 20081501
A8: COSTOS FIJOS
A9: Salarios y Cargas Sociales | B9: =Supuestos!$B$16 -> 3800000 | C9: =Supuestos!$B$16 -> 3800000 | D9: =Supuestos!$B$16 -> 3800000 | E9: =Supuestos!$B$16 -> 3800000 | F9: =Supuestos!$B$16 -> 3800000 | G9: =Supuestos!$B$16 -> 3800000 | H9: =Supuestos!$B$16 -> 3800000 | I9: =Supuestos!$B$16 -> 3800000 | ... KO9: =Supuestos!$B$16 -> 3800000
A10: Alquileres | B10: =Supuestos!$B$17 -> 1900000 | C10: =Supuestos!$B$17 -> 1900000 | D10: =Supuestos!$B$17 -> 1900000 | E10: =Supuestos!$B$17 -> 1900000 | F10: =Supuestos!$B$17 -> 1900000 | G10: =Supuestos!$B$17 -> 1900000 | H10: =Supuestos!$B$17 -> 1900000 | I10: =Supuestos!$B$17 -> 1900000 | ... KO10: =Supuestos!$B$17 -> 1900000
A11: Servicios | B11: =Supuestos!$B$18 -> 300000 | C11: =Supuestos!$B$18 -> 300000 | D11: =Supuestos!$B$18 -> 300000 | E11: =Supuestos!$B$18 -> 300000 | F11: =Supuestos!$B$18 -> 300000 | G11: =Supuestos!$B$18 -> 300000 | H11: =Supuestos!$B$18 -> 300000 | I11: =Supuestos!$B$18 -> 300000 | ... KO11: =Supuestos!$B$18 -> 300000
A12: Marketing y Publicidad | B12: =Supuestos!$B$19 -> 500000 | C12: =Supuestos!$B$19 -> 500000 | D12: =Supuestos!$B$19 -> 500000 | E12: =Supuestos!$B$19 -> 500000 | F12: =Supuestos!$B$19 -> 500000 | G12: =Supuestos!$B$19 -> 500000 | H12: =Supuestos!$B$19 -> 500000 | I12: =Supuestos!$B$19 -> 500000 | ... KO12: =Supuestos!$B$19 -> 500000
A13: Otros Gastos Fijos | B13: =Supuestos!$B$20 -> 400000 | C13: =Supuestos!$B$20 -> 400000 | D13: =Supuestos!$B$20 -> 400000 | E13: =Supuestos!$B$20 -> 400000 | F13: =Supuestos!$B$20 -> 400000 | G13: =Supuestos!$B$20 -> 400000 | H13: =Supuestos!$B$20 -> 400000 | I13: =Supuestos!$B$20 -> 400000 | ... KO13: =Supuestos!$B$20 -> 400000
A14: Total Costos Fijos | B14: =SUM(B9:B13) -> 6900000 | C14: =SUM(C9:C13) -> 6900000 | D14: =SUM(D9:D13) -> 6900000 | E14: =SUM(E9:E13) -> 6900000 | F14: =SUM(F9:F13) -> 6900000 | G14: =SUM(G9:G13) -> 6900000 | H14: =SUM(H9:H13) -> 6900000 | I14: =SUM(I9:I13) -> 6900000 | ... KO14: =SUM(KO9:KO13) -> 6900000
A16: Depreciación | B16: =Supuestos!$B$4/120 -> 416666.67 | C16: =Supuestos!$B$4/120 -> 416666.67 | D16: =Supuestos!$B$4/120 -> 416666.67 | E16: =Supuestos!$B$4/120 -> 416666.67 | F16: =Supuestos!$B$4/120 -> 416666.67 | G16: =Supuestos!$B$4/120 -> 416666.67 | H16: =Supuestos!$B$4/120 -> 416666.67 | I16: =Supuestos!$B$4/120 -> 416666.67 | ... DQ16: =Supuestos!$B$4/120 -> 416666.67 | DR16: 0 | DS16: 0 | DT16: 0 | DU16: 0 | DV16: 0 | DW16: 0 | DX16: 0 | DY16: 0 | DZ16: 0 | EA16: 0 | EB16: 0 | EC16: 0 | ED16: 0 | EE16: 0 | EF16: 0 | EG16: 0 | EH16: 0 | EI16: 0 | EJ16: 0 | EK16: 0 | EL16: 0 | EM16: 0 | EN16: 0 | EO16: 0 | EP16: 0 | EQ16: 0 | ER16: 0 | ES16: 0 | ET16: 0 | EU16: 0 | EV16: 0 | EW16: 0 | EX16: 0 | EY16: 0 | EZ16: 0 | FA16: 0 | FB16: 0 | FC16: 0 | FD16: 0 | FE16: 0 | FF16: 0 | FG16: 0 | FH16: 0 | FI16: 0 | FJ16: 0 | FK16: 0 | FL16: 0 | FM16: 0 | FN16: 0 | FO16: 0 | FP16: 0 | FQ16: 0 | FR16: 0 | FS16: 0 | FT16: 0 | FU16: 0 | FV16: 0 | FW16: 0 | FX16: 0 | FY16: 0 | FZ16: 0 | GA16: 0 | GB16: 0 | GC16: 0 | GD16: 0 | GE16: 0 | GF16: 0 | GG16: 0 | GH16: 0 | GI16: 0 | GJ16: 0 | GK16: 0 | GL16: 0 | GM16: 0 | GN16: 0 | GO16: 0 | GP16: 0 | GQ16: 0 | GR16: 0 | GS16: 0 | GT16: 0 | GU16: 0 | GV16: 0 | GW16: 0 | GX16: 0 | GY16: 0 | GZ16: 0 | HA16: 0 | HB16: 0 | HC16: 0 | HD16: 0 | HE16: 0 | HF16: 0 | HG16: 0 | HH16: 0 | HI16: 0 | HJ16: 0 | HK16: 0 | HL16: 0 | HM16: 0 | HN16: 0 | HO16: 0 | HP16: 0 | HQ16: 0 | HR16: 0 | HS16: 0 | HT16: 0 | HU16: 0 | HV16: 0 | HW16: 0 | HX16: 0 | HY16: 0 | HZ16: 0 | IA16: 0 | IB16: 0 | IC16: 0 | ID16: 0 | IE16: 0 | IF16: 0 | IG16: 0 | IH16: 0 | II16: 0 | IJ16: 0 | IK16: 0 | IL16: 0 | IM16: 0 | IN16: 0 | IO16: 0 | IP16: 0 | IQ16: 0 | IR16: 0 | IS16: 0 | IT16: 0 | IU16: 0 | IV16: 0 | IW16: 0 | IX16: 0 | IY16: 0 | IZ16: 0 | JA16: 0 | JB16: 0 | JC16: 0 | JD16: 0 | JE16: 0 | JF16: 0 | JG16: 0 | JH16: 0 | JI16: 0 | JJ16: 0 | JK16: 0 | JL16: 0 | JM16: 0 | JN16: 0 | JO16: 0 | JP16: 0 | JQ16: 0 | JR16: 0 | JS16: 0 | JT16: 0 | JU16: 0 | JV16: 0 | JW16: 0 | JX16: 0 | JY16: 0 | JZ16: 0 | KA16: 0 | KB16: 0 | KC16: 0 | KD16: 0 | KE16: 0 | KF16: 0 | KG16: 0 | KH16: 0 | KI16: 0 | KJ16: 0 | KK16: 0 | KL16: 0 | KM16: 0 | KN16: 0 | KO16: 0
A18: TOTAL COSTOS Y GASTOS | B18: =B6+B14+B16 -> 11275667 | C18: =C6+C14+C16 -> 11275667 | D18: =D6+D14+D16 -> 11275667 | E18: =E6+E14+E16 -> 11275667 | F18: =F6+F14+F16 -> 11275667 | G18: =G6+G14+G16 -> 11275667 | H18: =H6+H14+H16 -> 11275667 | I18: =I6+I14+I16 -> 11275667 | ... KO18: =KO6+KO14+KO16 -> 26981501

Sheet Estado de Resultados
A1: ESTADO DE RESULTADOS
A3: Concepto | B3: Mes 1 | C3: Mes 2 | D3: Mes 3 | E3: Mes 4 | F3: Mes 5 | G3: Mes 6 | H3: Mes 7 | I3: Mes 8 | J3: Mes 9 | K3: Mes 10 | L3: Mes 11 | M3: Mes 12 | N3: Mes 13 | O3: Mes 14 | P3: Mes 15 | Q3: Mes 16 | R3: Mes 17 | S3: Mes 18 | T3: Mes 19 | U3: Mes 20 | V3: Mes 21 | W3: Mes 22 | X3: Mes 23 | Y3: Mes 24 | Z3: Mes 25 | AA3: Mes 26 | AB3: Mes 27 | AC3: Mes 28 | AD3: Mes 29 | AE3: Mes 30 | AF3: Mes 31 | AG3: Mes 32 | AH3: Mes 33 | AI3: Mes 34 | AJ3: Mes 35 | AK3: Mes 36 | AL3: Mes 37 | AM3: Mes 38 | AN3: Mes 39 | AO3: Mes 40 | AP3: Mes 41 | AQ3: Mes 42 | AR3: Mes 43 | AS3: Mes 44 | AT3: Mes 45 | AU3: Mes 46 | AV3: Mes 47 | AW3: Mes 48 | AX3: Mes 49 | AY3: Mes 50 | AZ3: Mes 51 | BA3: Mes 52 | BB3: Mes 53 | BC3: Mes 54 | BD3: Mes 55 | BE3: Mes 56 | BF3: Mes 57 | BG3: Mes 58 | BH3: Mes 59 | BI3: Mes 60 | BJ3: Mes 61 | BK3: Mes 62 | BL3: Mes 63 | BM3: Mes 64 | BN3: Mes 65 | BO3: Mes 66 | BP3: Mes 67 | BQ3: Mes 68 | BR3: Mes 69 | BS3: Mes 70 | BT3: Mes 71 | BU3: Mes 72 | BV3: Mes 73 | BW3: Mes 74 | BX3: Mes 75 | BY3: Mes 76 | BZ3: Mes 77 | CA3: Mes 78 | CB3: Mes 79 | CC3: Mes 80 | CD3: Mes 81 | CE3: Mes 82 | CF3: Mes 83 | CG3: Mes 84 | CH3: Mes 85 | CI3: Mes 86 | CJ3: Mes 87 | CK3: Mes 88 | CL3: Mes 89 | CM3: Mes 90 | CN3: Mes 91 | CO3: Mes 92 | CP3: Mes 93 | CQ3: Mes 94 | CR3: Mes 95 | CS3: Mes 96 | CT3: Mes 97 | CU3: Mes 98 | CV3: Mes 99 | CW3: Mes 100 | CX3: Mes 101 | CY3: Mes 102 | CZ3: Mes 103 | DA3: Mes 104 | DB3: Mes 105 | DC3: Mes 106 | DD3: Mes 107 | DE3: Mes 108 | DF3: Mes 109 | DG3: Mes 110 | DH3: Mes 111 | DI3: Mes 112 | DJ3: Mes 113 | DK3: Mes 114 | DL3: Mes 115 | DM3: Mes 116 | DN3: Mes 117 | DO3: Mes 118 | DP3: Mes 119 | DQ3: Mes 120 | DR3: Mes 121 | DS3: Mes 122 | DT3: Mes 123 | DU3: Mes 124 | DV3: Mes 125 | DW3: Mes 126 | DX3: Mes 127 | DY3: Mes 128 | DZ3: Mes 129 | EA3: Mes 130 | EB3: Mes 131 | EC3: Mes 132 | ED3: Mes 133 | EE3: Mes 134 | EF3: Mes 135 | EG3: Mes 136 | EH3: Mes 137 | EI3: Mes 138 | EJ3: Mes 139 | EK3: Mes 140 | EL3: Mes 141 | EM3: Mes 142 | EN3: Mes 143 | EO3: Mes 144 | EP3: Mes 145 | EQ3: Mes 146 | ER3: Mes 147 | ES3: Mes 148 | ET3: Mes 149 | EU3: Mes 150 | EV3: Mes 151 | EW3: Mes 152 | EX3: Mes 153 | EY3: Mes 154 | EZ3: Mes 155 | FA3: Mes 156 | FB3: Mes 157 | FC3: Mes 158 | FD3: Mes 159 | FE3: Mes 160 | FF3: Mes 161 | FG3: Mes 162 | FH3: Mes 163 | FI3: Mes 164 | FJ3: Mes 165 | FK3: Mes 166 | FL3: Mes 167 | FM3: Mes 168 | FN3: Mes 169 | FO3: Mes 170 | FP3: Mes 171 | FQ3: Mes 172 | FR3: Mes 173 | FS3: Mes 174 | FT3: Mes 175 | FU3: Mes 176 | FV3: Mes 177 | FW3: Mes 178 | FX3: Mes 179 | FY3: Mes 180 | FZ3: Mes 181 | GA3: Mes 182 | GB3: Mes 183 | GC3: Mes 184 | GD3: Mes 185 | GE3: Mes 186 | GF3: Mes 187 | GG3: Mes 188 | GH3: Mes 189 | GI3: Mes 190 | GJ3: Mes 191 | GK3: Mes 192 | GL3: Mes 193 | GM3: Mes 194 | GN3: Mes 195 | GO3: Mes 196 | GP3: Mes 197 | GQ3: Mes 198 | GR3: Mes 199 | GS3: Mes 200 | GT3: Mes 201 | GU3: Mes 202 | GV3: Mes 203 | GW3: Mes 204 | GX3: Mes 205 | GY3: Mes 206 | GZ3: Mes 207 | HA3: Mes 208 | HB3: Mes 209 | HC3: Mes 210 | HD3: Mes 211 | HE3: Mes 212 | HF3: Mes 213 | HG3: Mes 214 | HH3: Mes 215 | HI3: Mes 216 | HJ3: Mes 217 | HK3: Mes 218 | HL3: Mes 219 | HM3: Mes 220 | HN3: Mes 221 | HO3: Mes 222 | HP3: Mes 223 | HQ3: Mes 224 | HR3: Mes 225 | HS3: Mes 226 | HT3: Mes 227 | HU3: Mes 228 | HV3: Mes 229 | HW3: Mes 230 | HX3: Mes 231 | HY3: Mes 232 | HZ3: Mes 233 | IA3: Mes 234 | IB3: Mes 235 | IC3: Mes 236 | ID3: Mes 237 | IE3: Mes 238 | IF3: Mes 239 | IG3: Mes 240 | IH3: Mes 241 | II3: Mes 242 | IJ3: Mes 243 | IK3: Mes 244 | IL3: Mes 245 | IM3: Mes 246 | IN3: Mes 247 | IO3: Mes 248 | IP3: Mes 249 | IQ3: Mes 250 | IR3: Mes 251 | IS3: Mes 252 | IT3: Mes 253 | IU3: Mes 254 | IV3: Mes 255 | IW3: Mes 256 | IX3: Mes 257 | IY3: Mes 258 | IZ3: Mes 259 | JA3: Mes 260 | JB3: Mes 261 | JC3: Mes 262 | JD3: Mes 263 | JE3: Mes 264 | JF3: Mes 265 | JG3: Mes 266 | JH3: Mes 267 | JI3: Mes 268 | JJ3: Mes 269 | JK3: Mes 270 | JL3: Mes 271 | JM3: Mes 272 | JN3: Mes 273 | JO3: Mes 274 | JP3: Mes 275 | JQ3: Mes 276 | JR3: Mes 277 | JS3: Mes 278 | JT3: Mes 279 | JU3: Mes 280 | JV3: Mes 281 | JW3: Mes 282 | JX3: Mes 283 | JY3: Mes 284 | JZ3: Mes 285 | KA3: Mes 286 | KB3: Mes 287 | KC3: Mes 288 | KD3: Mes 289 | KE3: Mes 290 | KF3: Mes 291 | KG3: Mes 292 | KH3: Mes 293 | KI3: Mes 294 | KJ3: Mes 295 | KK3: Mes 296 | KL3: Mes 297 | KM3: Mes 298 | KN3: Mes 299 | KO3: Mes 300
A4: Ingresos por Ventas | B4: =Ingresos!B6 -> 10700000 | C4: =Ingresos!C6 -> 10700000 | D4: =Ingresos!D6 -> 10700000 | E4: =Ingresos!E6 -> 10700000 | F4: =Ingresos!F6 -> 10700000 | G4: =Ingresos!G6 -> 10700000 | H4: =Ingresos!H6 -> 10700000 | I4: =Ingresos!I6 -> 10700000 | ... KO4: =Ingresos!KO6 -> 54274326
A5: Costos Variables | B5: =Costos!B6 -> 3959000 | C5: =Costos!C6 -> 3959000 | D5: =Costos!D6 -> 3959000 | E5: =Costos!E6 -> 3959000 | F5: =Costos!F6 -> 3959000 | G5: =Costos!G6 -> 3959000 | H5: =Costos!H6 -> 3959000 | I5: =Costos!I6 -> 3959000 | ... KO5: =Costos!KO6 -> 20081501
A6: MARGEN BRUTO | B6: =B4-B5 -> 6741000 | C6: =C4-C5 -> 6741000 | D6: =D4-D5 -> 6741000 | E6: =E4-E5 -> 6741000 | F6: =F4-F5 -> 6741000 | G6: =G4-G5 -> 6741000 | H6: =H4-H5 -> 6741000 | I6: =I4-I5 -> 6741000 | ... KO6: =KO4-KO5 -> 34192826
A8: Costos Fijos Operativos | B8: =Costos!B14 -> 6900000 | C8: =Costos!C14 -> 6900000 | D8: =Costos!D14 -> 6900000 | E8: =Costos!E14 -> 6900000 | F8: =Costos!F14 -> 6900000 | G8: =Costos!G14 -> 6900000 | H8: =Costos!H14 -> 6900000 | I8: =Costos!I14 -> 6900000 | ... KO8: =Costos!KO14 -> 6900000
A9: EBITDA | B9: =B6-B8 -> -159000 | C9: =C6-C8 -> -159000 | D9: =D6-D8 -> -159000 | E9: =E6-E8 -> -159000 | F9: =F6-F8 -> -159000 | G9: =G6-G8 -> -159000 | H9: =H6-H8 -> -159000 | I9: =I6-I8 -> -159000 | ... KO9: =KO6-KO8 -> 27292826
A10: Depreciación | B10: =Costos!B16 -> 416666.67 | C10: =Costos!C16 -> 416666.67 | D10: =Costos!D16 -> 416666.67 | E10: =Costos!E16 -> 416666.67 | F10: =Costos!F16 -> 416666.67 | G10: =Costos!G16 -> 416666.67 | H10: =Costos!H16 -> 416666.67 | I10: =Costos!I16 -> 416666.67 | ... KO10: =Costos!KO16 -> 0
A11: EBIT (Resultado Operativo) | B11: =B9-B10 -> -575666.67 | C11: =C9-C10 -> -575666.67 | D11: =D9-D10 -> -575666.67 | E11: =E9-E10 -> -575666.67 | F11: =F9-F10 -> -575666.67 | G11: =G9-G10 -> -575666.67 | H11: =H9-H10 -> -575666.67 | I11: =I9-I10 -> -575666.67 | ... KO11: =KO9-KO10 -> 27292826
A12: Gastos Financieros | B12: =Financiamiento!B6 -> 23333.333 | C12: =Financiamiento!C6 -> 23007.416 | D12: =Financiamiento!D6 -> 22679.598 | E12: =Financiamiento!E6 -> 22349.868 | F12: =Financiamiento!F6 -> 22018.214 | G12: =Financiamiento!G6 -> 21684.626 | H12: =Financiamiento!H6 -> 21349.092 | I12: =Financiamiento!I6 -> 21011.6 | ... KO12: =Financiamiento!KO6 -> 1.3292948e-10
A13: EBT (Utilidad antes de Impuestos) | B13: =B11-B12 -> -599000 | C13: =C11-C12 -> -598674.08 | D13: =D11-D12 -> -598346.27 | E13: =E11-E12 -> -598016.53 | F13: =F11-F12 -> -597684.88 | G13: =G11-G12 -> -597351.29 | H13: =H11-H12 -> -597015.76 | I13: =I11-I12 -> -596678.27 | ... KO13: =KO11-KO12 -> 27292826
A14: Impuestos | B14: =IF(B13>0,B13*'Panel de Control'!$B$15,0) -> 0 | C14: =IF(C13>0,C13*'Panel de Control'!$B$15,0) -> 0 | D14: =IF(D13>0,D13*'Panel de Control'!$B$15,0) -> 0 | E14: =IF(E13>0,E13*'Panel de Control'!$B$15,0) -> 0 | F14: =IF(F13>0,F13*'Panel de Control'!$B$15,0) -> 0 | G14: =IF(G13>0,G13*'Panel de Control'!$B$15,0) -> 0 | H14: =IF(H13>0,H13*'Panel de Control'!$B$15,0) -> 0 | I14: =IF(I13>0,I13*'Panel de Control'!$B$15,0) -> 0 | ... KO14: =IF(KO13>0,KO13*'Panel de Control'!$B$15,0) -> 7369062.9
A15: UTILIDAD NETA | B15: =B13-B14 -> -599000 | C15: =C13-C14 -> -598674.08 | D15: =D13-D14 -> -598346.27 | E15: =E13-E14 -> -598016.53 | F15: =F13-F14 -> -597684.88 | G15: =G13-G14 -> -597351.29 | H15: =H13-H14 -> -597015.76 | I15: =I13-I14 -> -596678.27 | ... KO15: =KO13-KO14 -> 19923763
A17: MÁRGENES
A18: Margen Bruto % | B18: =IF(B4<>0,B6/B4,0) -> 0.63 | C18: =IF(C4<>0,C6/C4,0) -> 0.63 | D18: =IF(D4<>0,D6/D4,0) -> 0.63 | E18: =IF(E4<>0,E6/E4,0) -> 0.63 | F18: =IF(F4<>0,F6/F4,0) -> 0.63 | G18: =IF(G4<>0,G6/G4,0) -> 0.63 | H18: =IF(H4<>0,H6/H4,0) -> 0.63 | I18: =IF(I4<>0,I6/I4,0) -> 0.63 | ... KO18: =IF(KO4<>0,KO6/KO4,0) -> 0.63
A19: Margen EBITDA % | B19: =IF(B4<>0,B9/B4,0) -> -0.014859813 | C19: =IF(C4<>0,C9/C4,0) -> -0.014859813 | D19: =IF(D4<>0,D9/D4,0) -> -0.014859813 | E19: =IF(E4<>0,E9/E4,0) -> -0.014859813 | F19: =IF(F4<>0,F9/F4,0) -> -0.014859813 | G19: =IF(G4<>0,G9/G4,0) -> -0.014859813 | H19: =IF(H4<>0,H9/H4,0) -> -0.014859813 | I19: =IF(I4<>0,I9/I4,0) -> -0.014859813 | ... KO19: =IF(KO4<>0,KO9/KO4,0) -> 0.50286807
A20: Margen Neto % | B20: =IF(B4<>0,B15/B4,0) -> -0.055981308 | C20: =IF(C4<>0,C15/C4,0) -> -0.055950849 | D20: =IF(D4<>0,D15/D4,0) -> -0.055920212 | E20: =IF(E4<>0,E15/E4,0) -> -0.055889396 | F20: =IF(F4<>0,F15/F4,0) -> -0.0558584 | G20: =IF(G4<>0,G15/G4,0) -> -0.055827224 | H20: =IF(H4<>0,H15/H4,0) -> -0.055795865 | I20: =IF(I4<>0,I15/I4,0) -> -0.055764324 | ... KO20: =IF(KO4<>0,KO15/KO4,0) -> 0.36709369

Sheet Financiamiento
A1: TABLA DE FINANCIAMIENTO
A3: Concepto | B3: Mes 1 | C3: Mes 2 | D3: Mes 3 | E3: Mes 4 | F3: Mes 5 | G3: Mes 6 | H3: Mes 7 | I3: Mes 8 | J3: Mes 9 | K3: Mes 10 | L3: Mes 11 | M3: Mes 12 | N3: Mes 13 | O3: Mes 14 | P3: Mes 15 | Q3: Mes 16 | R3: Mes 17 | S3: Mes 18 | T3: Mes 19 | U3: Mes 20 | V3: Mes 21 | W3: Mes 22 | X3: Mes 23 | Y3: Mes 24 | Z3: Mes 25 | AA3: Mes 26 | AB3: Mes 27 | AC3: Mes 28 | AD3: Mes 29 | AE3: Mes 30 | AF3: Mes 31 | AG3: Mes 32 | AH3: Mes 33 | AI3: Mes 34 | AJ3: Mes 35 | AK3: Mes 36 | AL3: Mes 37 | AM3: Mes 38 | AN3: Mes 39 | AO3: Mes 40 | AP3: Mes 41 | AQ3: Mes 42 | AR3: Mes 43 | AS3: Mes 44 | AT3: Mes 45 | AU3: Mes 46 | AV3: Mes 47 | AW3: Mes 48 | AX3: Mes 49 | AY3: Mes 50 | AZ3: Mes 51 | BA3: Mes 52 | BB3: Mes 53 | BC3: Mes 54 | BD3: Mes 55 | BE3: Mes 56 | BF3: Mes 57 | BG3: Mes 58 | BH3: Mes 59 | BI3: Mes 60 | BJ3: Mes 61 | BK3: Mes 62 | BL3: Mes 63 | BM3: Mes 64 | BN3: Mes 65 | BO3: Mes 66 | BP3: Mes 67 | BQ3: Mes 68 | BR3: Mes 69 | BS3: Mes 70 | BT3: Mes 71 | BU3: Mes 72 | BV3: Mes 73 | BW3: Mes 74 | BX3: Mes 75 | BY3: Mes 76 | BZ3: Mes 77 | CA3: Mes 78 | CB3: Mes 79 | CC3: Mes 80 | CD3: Mes 81 | CE3: Mes 82 | CF3: Mes 83 | CG3: Mes 84 | CH3: Mes 85 | CI3: Mes 86 | CJ3: Mes 87 | CK3: Mes 88 | CL3: Mes 89 | CM3: Mes 90 | CN3: Mes 91 | CO3: Mes 92 | CP3: Mes 93 | CQ3: Mes 94 | CR3: Mes 95 | CS3: Mes 96 | CT3: Mes 97 | CU3: Mes 98 | CV3: Mes 99 | CW3: Mes 100 | CX3: Mes 101 | CY3: Mes 102 | CZ3: Mes 103 | DA3: Mes 104 | DB3: Mes 105 | DC3: Mes 106 | DD3: Mes 107 | DE3: Mes 108 | DF3: Mes 109 | DG3: Mes 110 | DH3: Mes 111 | DI3: Mes 112 | DJ3: Mes 113 | DK3: Mes 114 | DL3: Mes 115 | DM3: Mes 116 | DN3: Mes 117 | DO3: Mes 118 | DP3: Mes 119 | DQ3: Mes 120 | DR3: Mes 121 | DS3: Mes 122 | DT3: Mes 123 | DU3: Mes 124 | DV3: Mes 125 | DW3: Mes 126 | DX3: Mes 127 | DY3: Mes 128 | DZ3: Mes 129 | EA3: Mes 130 | EB3: Mes 131 | EC3: Mes 132 | ED3: Mes 133 | EE3: Mes 134 | EF3: Mes 135 | EG3: Mes 136 | EH3: Mes 137 | EI3: Mes 138 | EJ3: Mes 139 | EK3: Mes 140 | EL3: Mes 141 | EM3: Mes 142 | EN3: Mes 143 | EO3: Mes 144 | EP3: Mes 145 | EQ3: Mes 146 | ER3: Mes 147 | ES3: Mes 148 | ET3: Mes 149 | EU3: Mes 150 | EV3: Mes 151 | EW3: Mes 152 | EX3: Mes 153 | EY3: Mes 154 | EZ3: Mes 155 | FA3: Mes 156 | FB3: Mes 157 | FC3: Mes 158 | FD3: Mes 159 | FE3: Mes 160 | FF3: Mes 161 | FG3: Mes 162 | FH3: Mes 163 | FI3: Mes 164 | FJ3: Mes 165 | FK3: Mes 166 | FL3: Mes 167 | FM3: Mes 168 | FN3: Mes 169 | FO3: Mes 170 | FP3: Mes 171 | FQ3: Mes 172 | FR3: Mes 173 | FS3: Mes 174 | FT3: Mes 175 | FU3: Mes 176 | FV3: Mes 177 | FW3: Mes 178 | FX3: Mes 179 | FY3: Mes 180 | FZ3: Mes 181 | GA3: Mes 182 | GB3: Mes 183 | GC3: Mes 184 | GD3: Mes 185 | GE3: Mes 186 | GF3: Mes 187 | GG3: Mes 188 | GH3: Mes 189 | GI3: Mes 190 | GJ3: Mes 191 | GK3: Mes 192 | GL3: Mes 193 | GM3: Mes 194 | GN3: Mes 195 | GO3: Mes 196 | GP3: Mes 197 | GQ3: Mes 198 | GR3: Mes 199 | GS3: Mes 200 | GT3: Mes 201 | GU3: Mes 202 | GV3: Mes 203 | GW3: Mes 204 | GX3: Mes 205 | GY3: Mes 206 | GZ3: Mes 207 | HA3: Mes 208 | HB3: Mes 209 | HC3: Mes 210 | HD3: Mes 211 | HE3: Mes 212 | HF3: Mes 213 | HG3: Mes 214 | HH3: Mes 215 | HI3: Mes 216 | HJ3: Mes 217 | HK3: Mes 218 | HL3: Mes 219 | HM3: Mes 220 | HN3: Mes 221 | HO3: Mes 222 | HP3: Mes 223 | HQ3: Mes 224 | HR3: Mes 225 | HS3: Mes 226 | HT3: Mes 227 | HU3: Mes 228 | HV3: Mes 229 | HW3: Mes 230 | HX3: Mes 231 | HY3: Mes 232 | HZ3: Mes 233 | IA3: Mes 234 | IB3: Mes 235 | IC3: Mes 236 | ID3: Mes 237 | IE3: Mes 238 | IF3: Mes 239 | IG3: Mes 240 | IH3: Mes 241 | II3: Mes 242 | IJ3: Mes 243 | IK3: Mes 244 | IL3: Mes 245 | IM3: Mes 246 | IN3: Mes 247 | IO3: Mes 248 | IP3: Mes 249 | IQ3: Mes 250 | IR3: Mes 251 | IS3: Mes 252 | IT3: Mes 253 | IU3: Mes 254 | IV3: Mes 255 | IW3: Mes 256 | IX3: Mes 257 | IY3: Mes 258 | IZ3: Mes 259 | JA3: Mes 260 | JB3: Mes 261 | JC3: Mes 262 | JD3: Mes 263 | JE3: Mes 264 | JF3: Mes 265 | JG3: Mes 266 | JH3: Mes 267 | JI3: Mes 268 | JJ3: Mes 269 | JK3: Mes 270 | JL3: Mes 271 | JM3: Mes 272 | JN3: Mes 273 | JO3: Mes 274 | JP3: Mes 275 | JQ3: Mes 276 | JR3: Mes 277 | JS3: Mes 278 | JT3: Mes 279 | JU3: Mes 280 | JV3: Mes 281 | JW3: Mes 282 | JX3: Mes 283 | JY3: Mes 284 | JZ3: Mes 285 | KA3: Mes 286 | KB3: Mes 287 | KC3: Mes 288 | KD3: Mes 289 | KE3: Mes 290 | KF3: Mes 291 | KG3: Mes 292 | KH3: Mes 293 | KI3: Mes 294 | KJ3: Mes 295 | KK3: Mes 296 | KL3: Mes 297 | KM3: Mes 298 | KN3: Mes 299 | KO3: Mes 300
A4: Saldo Inicial | B4: =Supuestos!$B$27 -> 4000000 | C4: =B7 -> 3944128.5 | D4: =C7 -> 3887931.2 | E4: =D7 -> 3831406 | F4: =E7 -> 3774551 | G4: =F7 -> 3717364.5 | H4: =G7 -> 3659844.3 | I4: =H7 -> 3601988.6 | J4: =I7 -> 3543795.4 | ... KO4: =KN7 -> 2.2787911e-08
